<?xml version="1.0" ?>
<sdf version="1.8">
    <model name='diff_drive'>
      <link name='chassis'>
        <pose>-0.151427 -0 0.175 0 -0 0</pose>
        <inertial>
          <!--
            FIX: Increased chassis mass from 1.14kg to 20kg.
            Original mass was absurdly low for a 2m×1m chassis while wheels
            were 2kg each. This caused top-heavy instability and jitter.
            A reasonable chassis should be the heaviest component.
          -->
          <mass>20</mass>
          <inertia>
            <!--
              FIX: Recalculated inertia for 20kg box (2.01m × 1m × 0.57m)
              Ixx = m/12*(y^2+z^2) = 20/12*(1+0.32) = 2.20
              Iyy = m/12*(x^2+z^2) = 20/12*(4.05+0.32) = 7.28
              Izz = m/12*(x^2+y^2) = 20/12*(4.05+1) = 8.42
            -->
            <ixx>2.20</ixx>
            <ixy>0</ixy>
            <ixz>0</ixz>
            <iyy>7.28</iyy>
            <iyz>0</iyz>
            <izz>8.42</izz>
          </inertia>
        </inertial>
        <visual name='visual_chassis'>
          <geometry>
            <box>
              <size>2.01142 1 0.568726</size>
            </box>
          </geometry>
          <material>
            <ambient>0.5 0.5 1.0 1</ambient>
            <diffuse>0.5 0.5 1.0 1</diffuse>
            <specular>0.0 0.0 1.0 1</specular>
          </material>
        </visual>
        <collision name='collision_chassis'>
          <geometry>
            <box>
              <size>2.01142 1 0.568726</size>
            </box>
          </geometry>
        </collision>
      </link>

      <link name='left_wheel'>
        <pose>0.554283 0.625029 -0.025 -1.5707 0 0</pose>
        <inertial>
          <mass>2</mass>
          <inertia>
            <ixx>0.145833</ixx>
            <ixy>0</ixy>
            <ixz>0</ixz>
            <iyy>0.145833</iyy>
            <iyz>0</iyz>
            <izz>0.125</izz>
          </inertia>
        </inertial>
        <visual name='visual_left_wheel'>
          <geometry>
            <sphere>
              <radius>0.3</radius>
            </sphere>
          </geometry>
          <material>
            <ambient>0.2 0.2 0.2 1</ambient>
            <diffuse>0.2 0.2 0.2 1</diffuse>
            <specular>0.2 0.2 0.2 1</specular>
          </material>
        </visual>
        <collision name='collision_left_wheel'>
          <geometry>
            <sphere>
              <radius>0.3</radius>
            </sphere>
          </geometry>
          <!--
            FIX: Added surface friction parameters for drive wheels.
            Without explicit friction, wheels slip excessively causing
            erratic motion and jitter. mu/mu2 = 1.0 provides good
            rubber-on-concrete traction.
          -->
          <surface>
            <friction>
              <ode>
                <mu>1.0</mu>
                <mu2>1.0</mu2>
                <slip1>0.0</slip1>
                <slip2>0.0</slip2>
              </ode>
            </friction>
            <contact>
              <ode>
                <!-- Stiff contact to prevent sinking into ground -->
                <kp>1e6</kp>
                <kd>100</kd>
                <max_vel>0.1</max_vel>
                <min_depth>0.001</min_depth>
              </ode>
            </contact>
          </surface>
        </collision>
      </link>

      <link name='right_wheel'>
        <pose>0.554282 -0.625029 -0.025 -1.5707 0 0</pose>
        <inertial>
          <mass>2</mass>
          <inertia>
            <ixx>0.145833</ixx>
            <ixy>0</ixy>
            <ixz>0</ixz>
            <iyy>0.145833</iyy>
            <iyz>0</iyz>
            <izz>0.125</izz>
          </inertia>
        </inertial>
        <visual name='visual_right_wheel'>
          <geometry>
            <sphere>
              <radius>0.3</radius>
            </sphere>
          </geometry>
          <material>
            <ambient>0.2 0.2 0.2 1</ambient>
            <diffuse>0.2 0.2 0.2 1</diffuse>
            <specular>0.2 0.2 0.2 1</specular>
          </material>
        </visual>
        <collision name='collision_right_wheel'>
          <geometry>
            <sphere>
              <radius>0.3</radius>
            </sphere>
          </geometry>
          <!-- FIX: Same friction as left wheel for symmetry -->
          <surface>
            <friction>
              <ode>
                <mu>1.0</mu>
                <mu2>1.0</mu2>
                <slip1>0.0</slip1>
                <slip2>0.0</slip2>
              </ode>
            </friction>
            <contact>
              <ode>
                <kp>1e6</kp>
                <kd>100</kd>
                <max_vel>0.1</max_vel>
                <min_depth>0.001</min_depth>
              </ode>
            </contact>
          </surface>
        </collision>
      </link>

      <link name='caster'>
        <pose>-0.957138 -0 -0.125 0 -0 0</pose>
        <inertial>
          <mass>1</mass>
          <inertia>
            <ixx>0.1</ixx>
            <ixy>0</ixy>
            <ixz>0</ixz>
            <iyy>0.1</iyy>
            <iyz>0</iyz>
            <izz>0.1</izz>
          </inertia>
        </inertial>
        <visual name='visual_caster'>
          <geometry>
            <sphere>
              <radius>0.2</radius>
            </sphere>
          </geometry>
          <material>
            <ambient>0.2 0.2 0.2 1</ambient>
            <diffuse>0.2 0.2 0.2 1</diffuse>
            <specular>0.2 0.2 0.2 1</specular>
          </material>
        </visual>
        <collision name='collision_caster'>
          <geometry>
            <sphere>
              <radius>0.2</radius>
            </sphere>
          </geometry>
          <!--
            FIX: Caster needs very low friction so it can freely
            follow the robot without resisting turns. mu=0.01 makes
            it nearly frictionless like a real caster wheel.
          -->
          <surface>
            <friction>
              <ode>
                <mu>0.01</mu>
                <mu2>0.01</mu2>
                <slip1>1.0</slip1>
                <slip2>1.0</slip2>
              </ode>
            </friction>
            <contact>
              <ode>
                <kp>1e6</kp>
                <kd>100</kd>
                <max_vel>0.1</max_vel>
                <min_depth>0.001</min_depth>
              </ode>
            </contact>
          </surface>
        </collision>
      </link>

      <link name="lidar_link">
        <pose>0 0 0.5 0 0 0</pose>
        <inertial>
          <mass>0.1</mass>
          <inertia>
            <ixx>0.000166667</ixx>
            <iyy>0.000166667</iyy>
            <izz>0.000166667</izz>
          </inertia>
        </inertial>
        <collision name="collision">
          <geometry>
            <box>
              <size>0.1 0.1 0.1</size>
            </box>
          </geometry>
        </collision>
        <visual name="visual">
          <geometry>
            <box>
              <size>0.1 0.1 0.1</size>
            </box>
          </geometry>
        </visual>
        <sensor name='gpu_lidar' type='gpu_lidar'>
          <pose>0 0 0 0 0 0</pose>
          <topic>scan</topic>
           <gz_frame_id>diff_drive/lidar_link</gz_frame_id>
          <update_rate>10</update_rate>
          <lidar>
            <scan>
              <horizontal>
                <samples>640</samples>
                <resolution>1</resolution>
                <min_angle>-1.396263</min_angle>
                <max_angle>1.396263</max_angle>
              </horizontal>
              <vertical>
                <samples>1</samples>
                <resolution>1</resolution>
                <min_angle>0.0</min_angle>
                <max_angle>0.0</max_angle>
              </vertical>
            </scan>
            <range>
              <min>0.08</min>
              <max>10.0</max>
              <resolution>0.01</resolution>
            </range>
          </lidar>
          <visualize>true</visualize>
        </sensor>
      </link>

      <joint name='lidar_joint' type='fixed'>
        <parent>chassis</parent>
        <child>lidar_link</child>
      </joint>

      <joint name='left_wheel_joint' type='revolute'>
        <parent>chassis</parent>
        <child>left_wheel</child>
        <axis>
          <xyz>0 0 1</xyz>
          <limit>
            <lower>-1.79769e+308</lower>
            <upper>1.79769e+308</upper>
          </limit>
          <!--
            FIX: Added damping to wheel joints to reduce oscillation.
            Without damping, wheels vibrate freely at contact discontinuities.
          -->
          <dynamics>
            <damping>0.5</damping>
            <friction>0.1</friction>
          </dynamics>
        </axis>
      </joint>

      <joint name='right_wheel_joint' type='revolute'>
        <parent>chassis</parent>
        <child>right_wheel</child>
        <axis>
          <xyz>0 0 1</xyz>
          <limit>
            <lower>-1.79769e+308</lower>
            <upper>1.79769e+308</upper>
          </limit>
          <!-- FIX: Same damping as left wheel -->
          <dynamics>
            <damping>0.5</damping>
            <friction>0.1</friction>
          </dynamics>
        </axis>
      </joint>

      <joint name='caster_wheel' type='ball'>
        <parent>chassis</parent>
        <child>caster</child>
      </joint>

      <plugin
        filename="ignition-gazebo-diff-drive-system"
        name="ignition::gazebo::systems::DiffDrive">
        <left_joint>left_wheel_joint</left_joint>
        <right_joint>right_wheel_joint</right_joint>
        <wheel_separation>1.25</wheel_separation>
        <wheel_radius>0.3</wheel_radius>
        <!--
          FIX: Increased odom_publish_frequency from 1 to 20 Hz.
          1 Hz caused extreme position jumps in odometry output,
          making the dashboard trajectory jerky and control unstable.
          20 Hz gives smooth pose updates without excessive CPU load.
        -->
        <odom_publish_frequency>20</odom_publish_frequency>
        <max_linear_acceleration>1</max_linear_acceleration>
        <min_linear_acceleration>-1</min_linear_acceleration>
        <max_angular_acceleration>2</max_angular_acceleration>
        <min_angular_acceleration>-2</min_angular_acceleration>
        <max_linear_velocity>0.5</max_linear_velocity>
        <min_linear_velocity>-0.5</min_linear_velocity>
        <max_angular_velocity>1</max_angular_velocity>
        <min_angular_velocity>-1</min_angular_velocity>
      </plugin>
    </model>
</sdf>
